<?xml version="1.0"?>
<robot name="fetch_webots" xmlns:xacro="http://ros.org/wiki/xacro">
  <link name="base_link">
  </link>
  <link name="torso_fixed_link">
  </link>
  <joint name="base_link_torso_fixed_link_joint" type="fixed">
    <parent link="base_link"/>
    <child link="torso_fixed_link"/>
    <origin xyz="-0.086875 0 0.377425" rpy="0 0 0"/>
  </joint>
  <link name="laser_link">
  </link>
  <joint name="base_link_laser_link_joint" type="fixed">
    <parent link="base_link"/>
    <child link="laser_link"/>
    <origin xyz="0.235 0 0.2878" rpy="-3.141592 0 0"/>
  </joint>
  <link name="camera">
  </link>
  <joint name="laser_link_camera_joint" type="fixed">
    <parent link="laser_link"/>
    <child link="camera"/>
    <origin xyz="0 0 -0.7" rpy="-4.712382 0 -1.570796"/>
  </joint>
  <link name="depth_camera">
  </link>
  <joint name="laser_link_depth_camera_joint" type="fixed">
    <parent link="laser_link"/>
    <child link="depth_camera"/>
    <origin xyz="0 0 -0.7" rpy="-3.141585 0 0"/>
  </joint>
  <link name="lidar2">
  </link>
  <joint name="laser_link_lidar2_joint" type="fixed">
    <parent link="laser_link"/>
    <child link="lidar2"/>
    <origin xyz="0 0 -0.7" rpy="0 0 0"/>
  </joint>
  <link name="lidar1">
  </link>
  <joint name="laser_link_lidar1_joint" type="fixed">
    <parent link="laser_link"/>
    <child link="lidar1"/>
    <origin xyz="0 0 0.1" rpy="0 0 0"/>
  </joint>
  <link name="estop_link">
  </link>
  <joint name="base_link_estop_link_joint" type="fixed">
    <parent link="base_link"/>
    <child link="estop_link"/>
    <origin xyz="-0.12465 0.23892 0.31127" rpy="1.5708 0 0"/>
  </joint>
  <joint name="torso_lift_joint" type="prismatic">
    <parent link="base_link"/>
    <child link="torso_lift_link"/>
    <axis xyz="0 0 1"/>
    <origin xyz="-0.086875 0 0.37743" rpy="0 0 0"/>
    <limit effort="450" lower="0" upper="0.38615" velocity="0.1"/>
  </joint>
  <link name="torso_lift_link">
  </link>
  <link name="bellows_link2">
  </link>
  <joint name="torso_lift_link_bellows_link2_joint" type="fixed">
    <parent link="torso_lift_link"/>
    <child link="bellows_link2"/>
    <origin xyz="0 0 -0.000286" rpy="0 0 0"/>
  </joint>
  <joint name="bellows_joint" type="prismatic">
    <parent link="torso_lift_link"/>
    <child link="bellows_link"/>
    <axis xyz="0 0 -1"/>
    <origin xyz="0 0 0" rpy="0 0 0"/>
    <limit effort="5" lower="0" upper="0.4" velocity="0.1"/>
  </joint>
  <link name="bellows_link">
  </link>
  <joint name="shoulder_pan_joint" type="revolute">
    <parent link="torso_lift_link"/>
    <child link="shoulder_pan_link"/>
    <axis xyz="0 0 1"/>
    <limit effort="33.82" lower="-1.6056" upper="1.6056" velocity="1.256"/>
    <origin xyz="0.119525 0 0.348578" rpy="0 0 0.500125"/>
  </joint>
  <link name="shoulder_pan_link">
  </link>
  <joint name="shoulder_lift_joint" type="revolute">
    <parent link="shoulder_pan_link"/>
    <child link="shoulder_lift_link"/>
    <axis xyz="0 1 0"/>
    <limit effort="131.76" lower="-1.221" upper="1.518" velocity="1.454"/>
    <origin xyz="0.117 0 0.06" rpy="0 0.000061 0"/>
  </joint>
  <link name="shoulder_lift_link">
  </link>
  <joint name="upperarm_roll_joint" type="continuous">
    <parent link="shoulder_lift_link"/>
    <child link="upperarm_roll_link"/>
    <axis xyz="1 0 0"/>
    <limit effort="76.94" velocity="1.571"/>
    <origin xyz="0.219 0 0" rpy="0.000001 0 0"/>
  </joint>
  <link name="upperarm_roll_link">
  </link>
  <joint name="elbow_flex_joint" type="revolute">
    <parent link="upperarm_roll_link"/>
    <child link="elbow_flex_link"/>
    <axis xyz="0 1 0"/>
    <limit effort="66.18" lower="-2.251" upper="2.251" velocity="1.521"/>
    <origin xyz="0.133 0 0" rpy="0 0.000025 0"/>
  </joint>
  <link name="elbow_flex_link">
  </link>
  <joint name="forearm_roll_joint" type="continuous">
    <parent link="elbow_flex_link"/>
    <child link="forearm_roll_link"/>
    <axis xyz="1 0 0"/>
    <limit effort="29.35" velocity="1.571"/>
    <origin xyz="0.197 0 0" rpy="0.000001 0 0"/>
  </joint>
  <link name="forearm_roll_link">
  </link>
  <joint name="wrist_flex_joint" type="revolute">
    <parent link="forearm_roll_link"/>
    <child link="wrist_flex_link"/>
    <axis xyz="0 1 0"/>
    <limit effort="25.7" lower="-2.16" upper="2.16" velocity="2.268"/>
    <origin xyz="0.1245 0 0" rpy="0 0.000005 0"/>
  </joint>
  <link name="wrist_flex_link">
  </link>
  <joint name="wrist_roll_joint" type="continuous">
    <parent link="wrist_flex_link"/>
    <child link="wrist_roll_link"/>
    <axis xyz="1 0 0"/>
    <limit effort="7.36" velocity="2.268"/>
    <origin xyz="0.1385 0 0" rpy="0.000016 0 0"/>
  </joint>
  <link name="wrist_roll_link">
  </link>
  <link name="gripper_link">
  </link>
  <joint name="wrist_roll_link_gripper_link_joint" type="fixed">
    <parent link="wrist_roll_link"/>
    <child link="gripper_link"/>
    <origin xyz="0.16645 0 0" rpy="0 0 0"/>
  </joint>
  <joint name="l_gripper_finger_joint" type="prismatic">
    <parent link="gripper_link"/>
    <child link="l_gripper_finger_link"/>
    <axis xyz="0 -1 0"/>
    <origin xyz="0 -0.015425 0" rpy="0 0 0"/>
    <limit effort="60" lower="0" upper="0.05" velocity="0.05"/>
  </joint>
  <link name="l_gripper_finger_link">
  </link>
  <joint name="r_gripper_finger_joint" type="prismatic">
    <parent link="gripper_link"/>
    <child link="r_gripper_finger_link"/>
    <axis xyz="0 1 0"/>
    <origin xyz="0 -0.034575 0" rpy="0 0 0"/>
    <limit effort="60" lower="0" upper="0.05" velocity="0.05"/>
  </joint>
  <link name="r_gripper_finger_link">
  </link>
  <joint name="head_pan_joint" type="revolute">
    <parent link="torso_lift_link"/>
    <child link="head_pan_link"/>
    <axis xyz="0 0 1"/>
    <limit effort="0.32" lower="-1.57" upper="1.57" velocity="1.57"/>
    <origin xyz="0.053125 0.05 0.603001" rpy="0 0 0"/>
  </joint>
  <link name="head_pan_link">
  </link>
  <joint name="head_tilt_joint" type="revolute">
    <parent link="head_pan_link"/>
    <child link="head_tilt_link"/>
    <axis xyz="0 1 0"/>
    <limit effort="0.68" lower="-0.76" upper="1.45" velocity="1.57"/>
    <origin xyz="0.14253 0 0.057999" rpy="0 0 0"/>
  </joint>
  <link name="head_tilt_link">
  </link>
  <joint name="l_wheel_joint" type="continuous">
    <parent link="base_link"/>
    <child link="l_wheel_link"/>
    <axis xyz="0 1 0"/>
    <limit effort="8.85" velocity="17.4"/>
    <origin xyz="0.001291 0.18738 0.055325" rpy="0 -0.019309 0"/>
  </joint>
  <link name="l_wheel_link">
  </link>
  <joint name="r_wheel_joint" type="continuous">
    <parent link="base_link"/>
    <child link="r_wheel_link"/>
    <axis xyz="0 1 0"/>
    <limit effort="8.85" velocity="17.4"/>
    <origin xyz="0.001291 -0.18738 0.055325" rpy="0 0.026059 0"/>
  </joint>
  <link name="r_wheel_link">
  </link>
</robot>
