#VRML_SIM R2025a utf8
# license: Apache License 2.0
# license url: http://www.apache.org/licenses/LICENSE-2.0
# This is a proto file for Webots for the fetch_webots
# Extracted from: C:\Users\Liraz Calif\Documents\FetchURDF\fetch.urdf

PROTO fetch_webots [
  field  SFVec3f     translation     0 0 0
  field  SFRotation  rotation        0 0 1 0
  field  SFString    name            "fetch_webots"  # Is `Robot.name`.
  field  SFString    controller      "void"          # Is `Robot.controller`.
  field  MFString    controllerArgs  []              # Is `Robot.controllerArgs`.
  field  SFString    customData      ""              # Is `Robot.customData`.
  field  SFBool      supervisor      FALSE           # Is `Robot.supervisor`.
  field  SFBool      synchronization TRUE            # Is `Robot.synchronization`.
  field  SFBool      selfCollision   FALSE           # Is `Robot.selfCollision`.
]
{
  Robot {
    translation IS translation
    rotation IS rotation
    controller IS controller
    controllerArgs IS controllerArgs
    customData IS customData
    supervisor IS supervisor
    synchronization IS synchronization
    selfCollision IS selfCollision
    children [
      DEF base_link_visual CadShape {
        url "fetch_description/meshes/base_link.dae"
      }
      HingeJoint {
        jointParameters HingeJointParameters {
          axis 0.000000 1.000000 0.000000
          anchor 0.001291 -0.187380 0.055325
        }
        device [
          RotationalMotor {
            name "r_wheel_joint"
            maxVelocity 17.4
            maxTorque 8.85
          }
          PositionSensor {
            name "r_wheel_joint_sensor"
          }
        ]
        endPoint Solid {
          translation 0.001291 -0.187380 0.055325
          children [
            Shape {
              appearance DEF r_wheel_link_material PBRAppearance {
                baseColor 0.086000 0.506000 0.767000
                roughness 1.000000
                metalness 0
              }
              geometry DEF r_wheel_link Mesh {
                url "fetch_description/meshes/r_wheel_link.STL"
              }
            }
          ]
          name "r_wheel_link"
          boundingObject DEF r_wheel_link_collision Cylinder {
            height 0.04
            radius 0.065
          }
          physics Physics {
            density -1
            mass 4.354200
            centerOfMass [ 0.000000 0.000000 0.000000 ]
            inertiaMatrix [
              4.500000e-03 5.000000e-03 4.500000e-03
              0.000000e+00 0.000000e+00 0.000000e+00
            ]
          }
        }
      }
      HingeJoint {
        jointParameters HingeJointParameters {
          axis 0.000000 1.000000 0.000000
          anchor 0.001291 0.187380 0.055325
        }
        device [
          RotationalMotor {
            name "l_wheel_joint"
            maxVelocity 17.4
            maxTorque 8.85
          }
          PositionSensor {
            name "l_wheel_joint_sensor"
          }
        ]
        endPoint Solid {
          translation 0.001291 0.187380 0.055325
          children [
            Shape {
              appearance DEF l_wheel_link_material PBRAppearance {
                baseColor 0.086000 0.506000 0.767000
                roughness 1.000000
                metalness 0
              }
              geometry DEF l_wheel_link Mesh {
                url "fetch_description/meshes/l_wheel_link.STL"
              }
            }
          ]
          name "l_wheel_link"
          boundingObject DEF l_wheel_link_collision Cylinder {
            height 0.04
            radius 0.065
          }
          physics Physics {
            density -1
            mass 4.354200
            centerOfMass [ 0.000000 0.000000 0.000000 ]
            inertiaMatrix [
              4.500000e-03 5.000000e-03 4.500000e-03
              0.000000e+00 0.000000e+00 0.000000e+00
            ]
          }
        }
      }
      SliderJoint {
        jointParameters JointParameters {
          axis 0.000000 0.000000 1.000000
          dampingConstant 100.0
        }
        device [
          LinearMotor {
            name "torso_lift_joint"
            maxVelocity 0.1
            maxPosition 0.38615
            maxForce 450.0
          }
          PositionSensor {
            name "torso_lift_joint_sensor"
          }
        ]
        endPoint Solid {
          translation -0.086875 0.000000 0.377430
          children [
            DEF torso_lift_link_visual CadShape {
              url "fetch_description/meshes/torso_lift_link.dae"
            }
            HingeJoint {
              jointParameters HingeJointParameters {
                axis 0.000000 0.000000 1.000000
                anchor 0.053125 0.000000 0.603001
              }
              device [
                RotationalMotor {
                  name "head_pan_joint"
                  maxVelocity 1.57
                  minPosition -1.57
                  maxPosition 1.57
                  maxTorque 0.32
                }
                PositionSensor {
                  name "head_pan_joint_sensor"
                }
              ]
              endPoint Solid {
                translation 0.053125 0.000000 0.603001
                children [
                  DEF head_pan_link_visual CadShape {
                    url "fetch_description/meshes/head_pan_link.dae"
                  }                  HingeJoint {
                    jointParameters HingeJointParameters {
                      axis 0.000000 1.000000 0.000000
                      anchor 0.142530 0.000000 0.057999
                    }
                    device [
                      RotationalMotor {
                        name "head_tilt_joint"
                        maxVelocity 1.57
                        minPosition -0.76
                        maxPosition 1.45
                        maxTorque 0.68
                      }
                      PositionSensor {
                        name "head_tilt_joint_sensor"
                      }
                    ]
                    endPoint Solid {
                      translation 0.142530 0.000000 0.057999
                      children [
                        DEF head_tilt_link_visual CadShape {
                          url "fetch_description/meshes/head_tilt_link.dae"
                        }
                      ]
                      name "head_tilt_link"
                      boundingObject DEF head_tilt_link_collision Mesh {
                        url "fetch_description/meshes/head_tilt_link_collision.STL"
                      }
                      physics Physics {
                        density -1
                        mass 0.908700
                        centerOfMass [ 0.008100 0.002500 0.011300 ]
                        inertiaMatrix [
                          6.100000e-03 1.400000e-03 6.100000e-03
                          -0.000000e+00 2.000000e-04 -1.000000e-04
                        ]
                      }
                    }
                  }
                ]
                name "head_pan_link"
                boundingObject DEF head_pan_link_collision Box  {
                   size 0.15 0.12 0.08
                }
                physics Physics {
                  density -1
                  mass 2.255600
                  centerOfMass [ 0.032100 0.016100 0.039000 ]
                  inertiaMatrix [
                    1.290000e-02 9.500000e-03 1.840000e-02
                    2.000000e-04 7.000000e-04 -0.000000e+00
                  ]
                }
              }
            }
            HingeJoint {
              jointParameters HingeJointParameters {
                axis 0.000000 0.000000 1.000000
                anchor 0.119525 0.000000 0.348580
                dampingConstant 1.0
              }
              device [
                RotationalMotor {
                  name "shoulder_pan_joint"
                  maxVelocity 1.256
                  minPosition -1.6056
                  maxPosition 1.6056
                  maxTorque 33.82
                }
                PositionSensor {
                  name "shoulder_pan_joint_sensor"
                }
              ]
              endPoint Solid {
                translation 0.119525 0.000000 0.348580
                children [
                  DEF shoulder_pan_link_visual CadShape {
                    url "fetch_description/meshes/shoulder_pan_link.dae"
                  }
                  HingeJoint {
                    jointParameters HingeJointParameters {
                      axis 0.000000 1.000000 0.000000
                      anchor 0.117000 0.000000 0.060000
                      dampingConstant 1.0
                    }
                    device [
                      RotationalMotor {
                        name "shoulder_lift_joint"
                        maxVelocity 1.454
                        minPosition -1.221
                        maxPosition 1.518
                        maxTorque 131.76
                      }
                      PositionSensor {
                        name "shoulder_lift_joint_sensor"
                      }
                    ]
                    endPoint Solid {
                      translation 0.117000 0.000000 0.060000
                      children [
                        DEF shoulder_lift_link_visual CadShape {
                          url "fetch_description/meshes/shoulder_lift_link.dae"
                        }
                        HingeJoint {
                          jointParameters HingeJointParameters {
                            anchor 0.219000 0.000000 0.000000
                            dampingConstant 5.0
                          }
                          device [
                            RotationalMotor {
                              name "upperarm_roll_joint"
                              maxVelocity 1.571
                              maxTorque 76.94
                            }
                            PositionSensor {
                              name "upperarm_roll_joint_sensor"
                            }
                          ]
                          endPoint Solid {
                            translation 0.219000 0.000000 0.000000
                            children [
                              DEF upperarm_roll_link_visual CadShape {
                                url "fetch_description/meshes/upperarm_roll_link.dae"
                              }
                              HingeJoint {
                                jointParameters HingeJointParameters {
                                  axis 0.000000 1.000000 0.000000
                                  anchor 0.133000 0.000000 0.000000
                                  dampingConstant 1.0
                                }
                                device [
                                  RotationalMotor {
                                    name "elbow_flex_joint"
                                    maxVelocity 1.521
                                    minPosition -2.251
                                    maxPosition 2.251
                                    maxTorque 66.18
                                  }
                                  PositionSensor {
                                    name "elbow_flex_joint_sensor"
                                  }
                                ]
                                endPoint Solid {
                                  translation 0.133000 0.000000 0.000000
                                  children [
                                    DEF elbow_flex_link_visual CadShape {
                                      url "fetch_description/meshes/elbow_flex_link.dae"
                                    }
                                    HingeJoint {
                                      jointParameters HingeJointParameters {
                                        anchor 0.197000 0.000000 0.000000
                                        dampingConstant 5.0
                                      }
                                      device [
                                        RotationalMotor {
                                          name "forearm_roll_joint"
                                          maxVelocity 1.571
                                          maxTorque 29.35
                                        }
                                        PositionSensor {
                                          name "forearm_roll_joint_sensor"
                                        }
                                      ]
                                      endPoint Solid {
                                        translation 0.197000 0.000000 0.000000
                                        children [
                                          DEF forearm_roll_link_visual CadShape {
                                            url "fetch_description/meshes/forearm_roll_link.dae"
                                          }
                                          HingeJoint {
                                            jointParameters HingeJointParameters {
                                              axis 0.000000 1.000000 0.000000
                                              anchor 0.124500 0.000000 0.000000
                                              dampingConstant 1.0
                                            }
                                            device [
                                              RotationalMotor {
                                                name "wrist_flex_joint"
                                                maxVelocity 2.268
                                                minPosition -2.16
                                                maxPosition 2.16
                                                maxTorque 25.7
                                              }
                                              PositionSensor {
                                                name "wrist_flex_joint_sensor"
                                              }
                                            ]
                                            endPoint Solid {
                                              translation 0.124500 0.000000 0.000000
                                              children [
                                                DEF wrist_flex_link_visual CadShape {
                                                  url "fetch_description/meshes/wrist_flex_link.dae"
                                                }
                                                HingeJoint {
                                                  jointParameters HingeJointParameters {
                                                    anchor 0.138500 0.000000 0.000000
                                                    dampingConstant 5.0
                                                  }
                                                  device [
                                                    RotationalMotor {
                                                      name "wrist_roll_joint"
                                                      maxVelocity 2.268
                                                      maxTorque 7.36
                                                    }
                                                    PositionSensor {
                                                      name "wrist_roll_joint_sensor"
                                                    }
                                                  ]
                                                  endPoint Solid {
                                                    translation 0.138500 0.000000 0.000000
                                                    children [
                                                      DEF wrist_roll_link_visual CadShape {
                                                        url "fetch_description/meshes/wrist_roll_link.dae"
                                                      }
                                                      Solid {
                                                        translation 0.166450 0.000000 0.000000
                                                        children [
                                                          DEF gripper_link_visual CadShape {
                                                            url "fetch_description/meshes/gripper_link.dae"
                                                          }
                                                          SliderJoint {
                                                            jointParameters JointParameters {
                                                              axis 0.000000 1.000000 0.000000
                                                              dampingConstant 100.0
                                                            }
                                                            device [
                                                              LinearMotor {
                                                                name "r_gripper_finger_joint"
                                                                maxVelocity 0.05
                                                                maxPosition 0.05
                                                                maxForce 60.0
                                                              }
                                                              PositionSensor {
                                                                name "r_gripper_finger_joint_sensor"
                                                              }
                                                            ]
                                                            endPoint Solid {
                                                              translation 0.000000 0.015425 0.000000
                                                              children [
                                                                Pose {
                                                                  translation 0.000000 0.101425 0.000000
                                                                  children [
                                                                    Shape {
                                                                      appearance DEF r_gripper_finger_link_material PBRAppearance {
                                                                        baseColor 0.356000 0.361000 0.376000
                                                                        roughness 1.000000
                                                                        metalness 0
                                                                      }
                                                                      geometry DEF r_gripper_finger_link Mesh {
                                                                        url "fetch_description/meshes/r_gripper_finger_link.STL"
                                                                      }
                                                                    }
                                                                  ]
                                                                }
                                                              ]
                                                              name "r_gripper_finger_link"
                                                              boundingObject Pose {
                                                                translation 0.000000 0.101425 0.000000
                                                                children [
                                                                  USE r_gripper_finger_link
                                                                ]
                                                              }
                                                              physics Physics {
                                                                density -1
                                                                mass 0.079800
                                                                centerOfMass [ -0.010000 0.000000 0.000000 ]
                                                              }
                                                            }
                                                          }
                                                          SliderJoint {
                                                            jointParameters JointParameters {
                                                              axis 0.000000 -1.000000 0.000000
                                                              dampingConstant 100.0
                                                            }
                                                            device [
                                                              LinearMotor {
                                                                name "l_gripper_finger_joint"
                                                                maxVelocity 0.05
                                                                maxPosition 0.05
                                                                maxForce 60.0
                                                              }
                                                              PositionSensor {
                                                                name "l_gripper_finger_joint_sensor"
                                                              }
                                                            ]
                                                            endPoint Solid {
                                                              translation 0.000000 -0.015425 0.000000
                                                              children [
                                                                Pose {
                                                                  translation 0.000000 -0.101425 0.000000
                                                                  children [
                                                                    Shape {
                                                                      appearance DEF l_gripper_finger_link_material PBRAppearance {
                                                                        baseColor 0.356000 0.361000 0.376000
                                                                        roughness 1.000000
                                                                        metalness 0
                                                                      }
                                                                      geometry DEF l_gripper_finger_link Mesh {
                                                                        url "fetch_description/meshes/l_gripper_finger_link.STL"
                                                                      }
                                                                    }
                                                                  ]
                                                                }
                                                              ]
                                                              name "l_gripper_finger_link"
                                                              boundingObject Pose {
                                                                translation 0.000000 -0.101425 0.000000
                                                                children [
                                                                  USE l_gripper_finger_link
                                                                ]
                                                              }
                                                              physics Physics {
                                                                density -1
                                                                mass 0.079800
                                                                centerOfMass [ -0.010000 0.000000 0.000000 ]
                                                              }
                                                            }
                                                          }
                                                        ]
                                                        name "gripper_link"
                                                        boundingObject DEF gripper_link Box {
                                                          size 0.08 0.04 0.16
                                                        }
                                                        physics Physics {
                                                          density -1
                                                          mass 1.517500
                                                          centerOfMass [ -0.090000 -0.000100 -0.001700 ]
                                                          inertiaMatrix [
                                                            1.300000e-03 1.900000e-03 2.400000e-03
                                                            -0.000000e+00 0.000000e+00 -0.000000e+00
                                                          ]
                                                        }
                                                      }
                                                    ]
                                                    name "wrist_roll_link"
                                                    boundingObject DEF wrist_roll_link_collision Box {
                                                      size 0.03 0.03 0.15
                                                    }
                                                    physics Physics {
                                                      density -1
                                                      mass 0.135400
                                                      centerOfMass [ 0.009500 0.000400 -0.000200 ]
                                                      inertiaMatrix [
                                                        1.000000e-04 1.000000e-04 1.000000e-04
                                                        0.000000e+00 0.000000e+00 0.000000e+00
                                                      ]
                                                    }
                                                  }
                                                }
                                              ]
                                              name "wrist_flex_link"
                                              boundingObject DEF wrist_flex_link_collision Box {
                                                size 0.05 0.05 0.12
                                              }
                                              physics Physics {
                                                density -1
                                                mass 1.725000
                                                centerOfMass [ 0.088200 0.000900 -0.000100 ]
                                                inertiaMatrix [
                                                  1.800000e-03 4.200000e-03 4.200000e-03
                                                  -1.000000e-04 -0.000000e+00 0.000000e+00
                                                ]
                                              }
                                            }
                                          }
                                        ]
                                        name "forearm_roll_link"
                                        boundingObject DEF forearm_roll_link_collision Box {
                                          size 0.12 0.05 0.05
                                        }
                                        physics Physics {
                                          density -1
                                          mass 1.656300
                                          centerOfMass [ 0.109700 -0.026600 0.000000 ]
                                          inertiaMatrix [
                                            1.600000e-03 3.000000e-03 3.500000e-03
                                            -3.000000e-04 0.000000e+00 -0.000000e+00
                                          ]
                                        }
                                      }
                                    }
                                  ]
                                  name "elbow_flex_link"
                                  boundingObject DEF elbow_flex_link_collision Box {
                                     size 0.15 0.05 0.05
                                  }
                                  physics Physics {
                                    density -1
                                    mass 2.129900
                                    centerOfMass [ 0.127900 0.007300 0.000000 ]
                                    inertiaMatrix [
                                      2.400000e-03 8.200000e-03 8.400000e-03
                                      -1.600000e-03 0.000000e+00 -0.000000e+00
                                    ]
                                  }
                                }
                              }
                            ]
                            name "upperarm_roll_link"
                            boundingObject DEF upperarm_roll_link_collision Cylinder {
                              radius 0.025    # approximate radius of the upper arm
                              height 0.22     # approximate length of the link
                            }
                            physics Physics {
                              density -1
                              mass 2.331100
                              centerOfMass [ 0.116500 0.001400 0.000000 ]
                              inertiaMatrix [
                                1.900000e-03 4.500000e-03 4.700000e-03
                                -1.000000e-04 0.000000e+00 0.000000e+00
                              ]
                            }
                          }
                        }
                      ]
                      name "shoulder_lift_link"
                      boundingObject DEF shoulder_lift_link_collision Box {
                        size 0.1 0.08 0.25
                      }
                      physics Physics {
                        density -1
                        mass 2.661500
                        centerOfMass [ 0.143200 0.007200 -0.000100 ]
                        inertiaMatrix [
                          2.800000e-03 1.110000e-02 1.120000e-02
                          -2.100000e-03 -0.000000e+00 -0.000000e+00
                        ]
                      }
                    }
                  }
                ]
                name "shoulder_pan_link"
                boundingObject DEF shoulder_pan_link_collision Box {
                  size 0.12 0.10 0.20
                }
                physics Physics {
                  density -1
                  mass 2.558700
                  centerOfMass [ 0.092700 -0.005600 0.056400 ]
                  inertiaMatrix [
                    4.300000e-03 8.700000e-03 8.700000e-03
                    -1.000000e-04 1.000000e-03 -1.000000e-04
                  ]
                }
              }
            }
            SliderJoint {
              jointParameters JointParameters {
                axis 0.000000 0.000000 -1.000000
              }
              device [
                LinearMotor {
                  name "bellows_joint"
                  maxVelocity 0.1
                  maxPosition 0.4
                  maxForce 5.0
                }
                PositionSensor {
                  name "bellows_joint_sensor"
                }
              ]
              endPoint Solid {
                children [
                  Shape {
                    appearance DEF bellows_link_material PBRAppearance {
                      baseColor 0.000000 0.000000 0.000000
                      roughness 1.000000
                      metalness 0
                    }
                    geometry DEF bellows_link Mesh {
                      url "fetch_description/meshes/bellows_link.STL"
                    }
                  }
                ]
                name "bellows_link"
                boundingObject DEF bellows_link_collision Box {
                  size 0.05 0.05 0.27
                }
                physics Physics {
                  density -1
                  mass 0.169374
                  centerOfMass [ 0.019132 -0.000000 -0.134862 ]
                  inertiaMatrix [
                    3.311591e-03 1.744473e-03 1.694176e-03
                    -8.923096e-18 -5.386222e-08 -8.069650e-17
                  ]
                }
              }
            }
            Solid {
              children [
                Shape {
                  appearance DEF bellows_link2_material PBRAppearance {
                    baseColor 0.000000 0.000000 0.000000
                    roughness 1.000000
                    metalness 0
                  }
                  geometry USE bellows_link
                }
              ]
              name "bellows_link2"
              boundingObject USE bellows_link_collision
              physics Physics {
                density -1
                mass 0.169374
                centerOfMass [ 0.019132 -0.000000 -0.134862 ]
                inertiaMatrix [
                  3.311591e-03 1.744473e-03 1.694176e-03
                  -8.923096e-18 -5.386222e-08 -8.069650e-17
                ]
              }
            }
          ]
          name "torso_lift_link"
          boundingObject DEF torso_lift_link_collision Box {
            size 0.2 0.4 0.6
          }
          physics Physics {
            density -1
            mass 10.779600
            centerOfMass [ -0.001300 -0.000900 0.293500 ]
            inertiaMatrix [
              3.354000e-01 3.354000e-01 9.540000e-02
              0.000000e+00 -1.620000e-02 -6.000000e-04
            ]
          }
        }
      }
      Solid {
        translation -0.124650 0.238920 0.311270
        rotation 1.000000 0.000000 0.000000 1.570800
        children [
          DEF estop_link_visual CadShape {
            url "fetch_description/meshes/estop_link.dae"
          }
        ]
        name "estop_link"
        boundingObject DEF estop_link Box {
          size 0.02 0.02 0.02
        }
        physics Physics {
          density -1
          mass 0.001961
          centerOfMass [ 0.002435 -0.003306 0.006651 ]
          inertiaMatrix [
            3.028100e-07 2.933229e-07 2.285133e-07
            -1.586202e-08 3.165614e-08 -4.288335e-08
          ]
        }
      }
      Solid {
        translation 0.235000 0.000000 0.287800
        rotation 1.000000 0.000000 -0.000000 3.141593
        children [
          Shape {
            appearance DEF laser_link_material PBRAppearance {
              baseColor 0.792157 0.819608 0.933333
              roughness 1.000000
              metalness 0
            }
            geometry DEF laser_link Mesh {
              url "fetch_description/meshes/laser_link.STL"
            }
          }	
    	  Transform {
      	    translation 0 0 0.1
            children [
              Lidar {
                name "lidar1"
                horizontalResolution 360
          	numberOfLayers 1
          	minFrequency 10
          	maxFrequency 10
          	minRange 0.05
          	maxRange 10.0
      	      }
      	    ]
    	  }
    	  Transform {
      	    translation 0 0 -0.7
            children [
              Lidar {
                name "lidar2"
                horizontalResolution 360
          	numberOfLayers 1
          	minFrequency 10
          	maxFrequency 10
          	minRange 0.05
          	maxRange 10.0
      	      }
      	    ]
    	  }
  	Transform {
      	    translation 0 0 -0.7
	    rotation 1 0 0 3.1416
            children [
              RangeFinder {
		 name "depth_camera"
    		width 1280
    		height 720		
    		fieldOfView 1.047
		maxRange 10
		}
      	   ]
    	 }

    	  Transform {
      	    translation 0 0 -0.7
	    rotation 1 0 0 3.1416
            children [
              Camera {
          	name "camera"
  		width 1280
  		height 720
  		fieldOfView 1.047
  		near 0.01
  		far 100
              }
      	   ]
    	 }
        ]
        name "laser_link"
        boundingObject USE laser_link
        physics Physics {
          density -1
          mass 0.008336
          centerOfMass [ -0.030623 0.000709 0.055197 ]
          inertiaMatrix [
            1.018665e-06 5.100396e-07 1.282707e-06
            -5.884476e-08 7.838572e-08 -7.126643e-09
          ]
        }
      }

      Solid {
        translation -0.086875 0.000000 0.377425
        children [
          DEF torso_fixed_link_visual CadShape {
            url "fetch_description/meshes/torso_fixed_link.dae"
          }
        ]
        name "torso_fixed_link"
        boundingObject DEF torso_fixed_link Box {
          size 0.4 0.35 0.3
        }
        physics Physics {
          density -1
          mass 13.277500
          centerOfMass [ -0.072200 0.005700 0.265600 ]
          inertiaMatrix [
            3.861000e-01 3.388000e-01 1.018000e-01
            1.500000e-03 -1.020000e-02 1.170000e-02
          ]
        }
      }
    ]
    name IS name
    boundingObject DEF base_link_collision Box {
      size 0.45 0.35 0.12
    }
    physics Physics {
      density -1
      mass 70.129400
      centerOfMass [ -0.003600 0.000000 0.001400 ]
      inertiaMatrix [
        1.225000e+00 1.285300e+00 9.870000e-01
        9.900000e-03 6.200000e-03 -3.400000e-03
      ]
    }
  }
}
